Workbook

Sheet Upload
A1: =IF(DB!A1="","",DB!A1) -> 商品コード | B1: =IF(DB!B1="","",DB!B1) -> 商品名 | C1: =IF(DB!C1="","",DB!C1) -> メーカー | D1: =IF(DB!D1="","",DB!D1) -> 標準原価 | E1: 設定モード | F1: =IF(DB!F1="","",DB!F1) -> 納期区分 | G1: A | H1: B | I1: C | J1: D | K1: E | L1: F | M1: G | N1: P
A2: =IF(DB!A2="","",DB!A2) | B2: =IF(DB!B2="","",DB!B2) -> RICOH SP ﾄﾅ- 8400 | C2: =IF(DB!C2="","",DB!C2) -> RICOH | D2: =IF(DB!D2="","",DB!D2) | E2: =IF(DB!E2="","",DB!E2) -> 自動 | F2: =IF(DB!F2="","",DB!F2) | G2: =IF(DB!G2="","",DB!G2) -> 44754 | H2: =IF(DB!H2="","",DB!H2) -> 44754 | ... J2: =IF(DB!J2="","",DB!J2)
A3: =IF(DB!A3="","",DB!A3) | B3: =IF(DB!B3="","",DB!B3) -> RICOH SP ﾄﾞﾗﾑﾕﾆﾂﾄ 8400 | C3: =IF(DB!C3="","",DB!C3) -> RICOH | D3: =IF(DB!D3="","",DB!D3) | E3: =IF(DB!E3="","",DB!E3) -> 自動 | F3: =IF(DB!F3="","",DB!F3) | G3: =IF(DB!G3="","",DB!G3) -> 32270 | H3: =IF(DB!H3="","",DB!H3) -> 32270 | ... J3: =IF(DB!J3="","",DB!J3)
A4: =IF(DB!A4="","",DB!A4) | B4: =IF(DB!B4="","",DB!B4) -> IPSIO SPﾄﾅ- 8200 | C4: =IF(DB!C4="","",DB!C4) -> RICOH | D4: =IF(DB!D4="","",DB!D4) | E4: =IF(DB!E4="","",DB!E4) -> 自動 | F4: =IF(DB!F4="","",DB!F4) | G4: =IF(DB!G4="","",DB!G4) -> 32513 | H4: =IF(DB!H4="","",DB!H4) -> 32513 | ... J4: =IF(DB!J4="","",DB!J4)
A5: =IF(DB!A5="","",DB!A5) | B5: =IF(DB!B5="","",DB!B5) -> ｲﾌﾟｼｵ SP ﾄﾞﾗﾑﾕﾆﾂﾄ 8300 | C5: =IF(DB!C5="","",DB!C5) -> RICOH | D5: =IF(DB!D5="","",DB!D5) | E5: =IF(DB!E5="","",DB!E5) -> 自動 | F5: =IF(DB!F5="","",DB!F5) | G5: =IF(DB!G5="","",DB!G5) -> 32270 | H5: =IF(DB!H5="","",DB!H5) -> 32270 | ... J5: =IF(DB!J5="","",DB!J5)
A6: =IF(DB!A6="","",DB!A6) | B6: =IF(DB!B6="","",DB!B6) -> IPSIO SP ﾄﾞﾗﾑﾕﾆﾂﾄ 8200 | C6: =IF(DB!C6="","",DB!C6) -> RICOH | D6: =IF(DB!D6="","",DB!D6) | E6: =IF(DB!E6="","",DB!E6) -> 自動 | F6: =IF(DB!F6="","",DB!F6) | G6: =IF(DB!G6="","",DB!G6) -> 32513 | H6: =IF(DB!H6="","",DB!H6) -> 32513 | ... J6: =IF(DB!J6="","",DB!J6)
A7: =IF(DB!A7="","",DB!A7) | B7: =IF(DB!B7="","",DB!B7) -> RICOH SP ﾄﾅ- 6400 | C7: =IF(DB!C7="","",DB!C7) -> RICOH | D7: =IF(DB!D7="","",DB!D7) | E7: =IF(DB!E7="","",DB!E7) -> 自動 | F7: =IF(DB!F7="","",DB!F7) | G7: =IF(DB!G7="","",DB!G7) -> 14453 | H7: =IF(DB!H7="","",DB!H7) -> 14453 | ... J7: =IF(DB!J7="","",DB!J7)
A8: =IF(DB!A8="","",DB!A8) | B8: =IF(DB!B8="","",DB!B8) -> RICOH SP ﾄﾅ- 6400H | C8: =IF(DB!C8="","",DB!C8) -> RICOH | D8: =IF(DB!D8="","",DB!D8) | E8: =IF(DB!E8="","",DB!E8) -> 自動 | F8: =IF(DB!F8="","",DB!F8) | G8: =IF(DB!G8="","",DB!G8) -> 22261 | H8: =IF(DB!H8="","",DB!H8) -> 22261 | ... J8: =IF(DB!J8="","",DB!J8)
A9: =IF(DB!A9="","",DB!A9) | B9: =IF(DB!B9="","",DB!B9) -> RICOH SP ﾄﾞﾗﾑﾕﾆﾂﾄ 6400 | C9: =IF(DB!C9="","",DB!C9) -> RICOH | D9: =IF(DB!D9="","",DB!D9) | E9: =IF(DB!E9="","",DB!E9) -> 自動 | F9: =IF(DB!F9="","",DB!F9) | G9: =IF(DB!G9="","",DB!G9) -> 9163 | H9: =IF(DB!H9="","",DB!H9) -> 9094 | ... J9: =IF(DB!J9="","",DB!J9)
A10: =IF(DB!A10="","",DB!A10) | B10: =IF(DB!B10="","",DB!B10) -> IPSIO SP ﾄﾅ-ｶ-ﾄﾘﾂｼﾞ6100 | C10: =IF(DB!C10="","",DB!C10) -> RICOH | D10: =IF(DB!D10="","",DB!D10) | E10: =IF(DB!E10="","",DB!E10) -> 自動 | F10: =IF(DB!F10="","",DB!F10) | G10: =IF(DB!G10="","",DB!G10) -> 24236 | H10: =IF(DB!H10="","",DB!H10) -> 23871 | ... J10: =IF(DB!J10="","",DB!J10)
A11: =IF(DB!A11="","",DB!A11) | B11: =IF(DB!B11="","",DB!B11) -> IPSIO SP ﾄﾅ-ｶ-ﾄﾘﾂｼﾞ6100H | C11: =IF(DB!C11="","",DB!C11) -> RICOH | D11: =IF(DB!D11="","",DB!D11) | E11: =IF(DB!E11="","",DB!E11) -> 自動 | F11: =IF(DB!F11="","",DB!F11) | G11: =IF(DB!G11="","",DB!G11) -> 48472 | H11: =IF(DB!H11="","",DB!H11) -> 47742 | ... J11: =IF(DB!J11="","",DB!J11)
A12: =IF(DB!A12="","",DB!A12) | B12: =IF(DB!B12="","",DB!B12) -> IPSIO SP ECﾄﾅ-ｶ-ﾄﾘﾂｼﾞ 6100 | C12: =IF(DB!C12="","",DB!C12) -> RICOH | D12: =IF(DB!D12="","",DB!D12) | E12: =IF(DB!E12="","",DB!E12) -> 自動 | F12: =IF(DB!F12="","",DB!F12) | G12: =IF(DB!G12="","",DB!G12) -> 21912 | H12: =IF(DB!H12="","",DB!H12) -> 21417 | ... J12: =IF(DB!J12="","",DB!J12)
A13: =IF(DB!A13="","",DB!A13) | B13: =IF(DB!B13="","",DB!B13) -> IPSIO SP ECﾄﾅ-ｶ-ﾄﾘﾂｼﾞ 6100H | C13: =IF(DB!C13="","",DB!C13) -> RICOH | D13: =IF(DB!D13="","",DB!D13) | E13: =IF(DB!E13="","",DB!E13) -> 自動 | F13: =IF(DB!F13="","",DB!F13) | G13: =IF(DB!G13="","",DB!G13) -> 43558 | H13: =IF(DB!H13="","",DB!H13) -> 42574 | ... J13: =IF(DB!J13="","",DB!J13)
... A9285: =IF(DB!A9285="","",DB!A9285) | B9285: =IF(DB!B9285="","",DB!B9285) | C9285: =IF(DB!C9285="","",DB!C9285) | D9285: =IF(DB!D9285="","",DB!D9285) | E9285: =IF(DB!E9285="","",DB!E9285) | F9285: =IF(DB!F9285="","",DB!F9285) | G9285: =IF(DB!G9285="","",DB!G9285) | H9285: =IF(DB!H9285="","",DB!H9285) | ... J9285: =IF(DB!J9285="","",DB!J9285)

Sheet DB
A1: 商品コード | B1: 商品名 | C1: メーカー | D1: 標準原価 | E1: 設定モード | F1: 納期区分 | G1: パターン1 | H1: パターン2 | I1: パターン3 | J1: パターン4 | K1: 商品コード | L1: 商品名 | M1: 仕様 | N1: 定価
B2: RICOH SP ﾄﾅ- 8400 | C2: RICOH | E2: 自動 | G2: 44754 | H2: 44754 | K2: 0000 | L2: フリー | M2: 純正
B3: RICOH SP ﾄﾞﾗﾑﾕﾆﾂﾄ 8400 | C3: RICOH | E3: 自動 | G3: 32270 | H3: 32270 | K3: 00000014 | L3: EPSON A3モノクロページプリンター LP-S3250
B4: IPSIO SPﾄﾅ- 8200 | C4: RICOH | E4: 自動 | G4: 32513 | H4: 32513 | K4: 00000015 | L4: アクリルパーテーション 60X60 窓付き 4枚ｾｯﾄ
B5: ｲﾌﾟｼｵ SP ﾄﾞﾗﾑﾕﾆﾂﾄ 8300 | C5: RICOH | E5: 自動 | G5: 32270 | H5: 32270 | K5: 00000016 | L5: EPSON A4ｶﾗｰｲﾝｸｼﾞｪｯﾄ PX-S740
B6: IPSIO SP ﾄﾞﾗﾑﾕﾆﾂﾄ 8200 | C6: RICOH | E6: 自動 | G6: 32513 | H6: 32513 | K6: 315253 | L6: RICOH PPCｽﾃｰﾌﾟﾗｰ針 ﾀｲﾌﾟN 5000針×2個/箱 315253 | M6: 純正 | N6: 3200
B7: RICOH SP ﾄﾅ- 6400 | C7: RICOH | E7: 自動 | G7: 14453 | H7: 14453 | K7: 319167 | L7: RICOH PPCｽﾃｰﾌﾟﾗｰ ｶｰﾄﾘｯｼﾞ ﾀｲﾌﾟV 5000 319167 3251638 | M7: 純正 | N7: 2400
B8: RICOH SP ﾄﾅ- 6400H | C8: RICOH | E8: 自動 | G8: 22261 | H8: 22261 | K8: 3410SD | L8: 富士ﾌｲﾙﾑ ﾚｰｻﾞｰﾌﾟﾘﾝﾀｰ ApeosPort Print 3410SD (NL300086) | M8: 純正
B9: RICOH SP ﾄﾞﾗﾑﾕﾆﾂﾄ 6400 | C9: RICOH | E9: 自動 | G9: 9163 | H9: 9094 | K9: 3ED28A | L9: HP712B ｲﾝｸｶｰﾄﾘｯｼﾞ 3ED28A ﾌﾞﾗｯｸ 38ml | M9: 純正 | N9: 4100
B10: IPSIO SP ﾄﾅ-ｶ-ﾄﾘﾂｼﾞ6100 | C10: RICOH | E10: 自動 | G10: 24236 | H10: 23871 | K10: 3ED67A | L10: HP712 ｲﾝｸｶｰﾄﾘｯｼﾞ 3ED67A ｼｱﾝ 29ml | M10: 純正 | N10: 3400
B11: IPSIO SP ﾄﾅ-ｶ-ﾄﾘﾂｼﾞ6100H | C11: RICOH | E11: 自動 | G11: 48472 | H11: 47742 | K11: 3ED68A | L11: HP712 ｲﾝｸｶｰﾄﾘｯｼﾞ 3ED68A ﾏｾﾞﾝﾀ 29ml | M11: 純正 | N11: 3400
B12: IPSIO SP ECﾄﾅ-ｶ-ﾄﾘﾂｼﾞ 6100 | C12: RICOH | E12: 自動 | G12: 21912 | H12: 21417 | K12: 3ED69A | L12: HP712 ｲﾝｸｶｰﾄﾘｯｼﾞ 3ED69A ｲｴﾛｰ 29ml | M12: 純正 | N12: 3400
B13: IPSIO SP ECﾄﾅ-ｶ-ﾄﾘﾂｼﾞ 6100H | C13: RICOH | E13: 自動 | G13: 43558 | H13: 42574 | K13: 4020SD | L13: 富士ﾌｲﾙﾑ ﾚｰｻﾞｰﾌﾟﾘﾝﾀｰ ApeosPort Print 4020SD (NL300085) | M13: 純正
B14: RICOH ドラムユニット P6000 | C14: RICOH | E14: 自動 | G14: 9163 | H14: 9163 | K14: 51645AA | L14: HP45 ﾌﾟﾘﾝﾄｶｰﾄﾘｯｼﾞ 黒 51645AA#003 | M14: 純正
B15: RICOH SP ﾄﾅ- 4500L | C15: RICOH | E15: 自動 | G15: 8898 | H15: 8898 | K15: 527F9A | L15: HP LaserJet ﾄﾅｰｺﾚｸｼｮﾝﾕﾆｯﾄ 527F9A | M15: 純正 | N15: 9145
B16: RICOH SP ﾄﾅ- 4500 | C16: RICOH | E16: 自動 | G16: 14323 | H16: 14323 | K16: 527G0A | L16: HP LJ ﾌｭｰｻﾞｰｷｯﾄ 527G0A | M16: 純正 | N16: 62682
B17: RICOH SP ﾄﾅ- 4500H | C17: RICOH | E17: 自動 | G17: 22432 | H17: 22432 | K17: 527G2A | L17: HP LaserJet ｴﾝﾊﾝｽﾌｭｰｻﾞｰｷｯﾄ 527G2A | M17: 純正 | N17: 102609
B18: RICOH SP ﾄﾞﾗﾑﾕﾆﾂﾄ 4500 | C18: RICOH | E18: 自動 | G18: 7481 | H18: 7481 | K18: 527G6A | L18: HP LJ ｴﾝﾊﾝｽﾌｭｰｻﾞｰｷｯﾄ 527G6A | M18: 純正 | N18: 70191
B19: IPSIO SP ﾄﾅ-ｶ-ﾄﾘﾂｼﾞ4200 | C19: RICOH | E19: 自動 | G19: 21647 | H19: 21647 | K19: 527G9A | L19: HP LJ ｲﾒｰｼﾞﾄﾗﾝｽﾌｧｰﾍﾞﾙﾄｷｯﾄ 527G9A | M19: 純正 | N19: 87682
B20: IPSIO SP ﾄﾅ-ｶ-ﾄﾘﾂｼﾞ4200H | C20: RICOH | E20: 自動 | G20: 34662 | H20: 34662 | K20: 527H2A | L20: HP LJ ﾄﾚｲﾛｰﾗｰｷｯﾄ(ﾄﾚｲ2用) 527H2A | M20: 純正 | N20: 9273
B21: IPSIO SP ECﾄﾅ-ｶ-ﾄﾘﾂｼﾞ 4200 | C21: RICOH | E21: 自動 | G21: 19405 | H21: 19405 | K21: 527H3A | L21: HP LJ ﾄﾚｲﾛｰﾗｰｷｯﾄ(ﾄﾚｲ1用) 527H3A | M21: 純正 | N21: 9345
B22: IPSIO SP ECﾄﾅ-ｶ-ﾄﾘﾂｼﾞ 4200H | C22: RICOH | E22: 自動 | G22: 30957 | H22: 30957 | K22: 6H122A | L22: HP LaserJet ADFﾒﾝﾃﾅﾝｽｷｯﾄ 6H122A | M22: 純正 | N22: 13064
B23: RICOH トナー P 500L | C23: RICOH | E23: 自動 | G23: 9098 | H23: 9098 | K23: B432dnw | L23: OKI ﾚｰｻﾞｰﾌﾟﾘﾝﾀｰ B432dnw
B24: RICOH トナー P 500 | C24: RICOH | E24: 自動 | G24: 24338 | H24: 24338 | K24: B6Y01A | L24: HP HP771B ｲﾝｸｶｰﾄﾘｯｼﾞ ﾏｾﾞﾝﾀ B6Y01A | M24: 純正 | N24: 41900
B25: RICOH トナー P 500H | C25: RICOH | E25: 自動 | G25: 32061 | H25: 32061 | K25: B6Y03A | L25: HP HP771B ｲﾝｸｶｰﾄﾘｯｼﾞ ﾗｲﾄﾏｾﾞﾝﾀ B6Y03A | M25: 純正 | N25: 41900
B26: RICOH ドラムユニット P 500 | C26: RICOH | E26: 自動 | G26: 11576 | H26: 11576 | K26: B6Y04A | L26: HP HP771B ｲﾝｸｶｰﾄﾘｯｼﾞ ﾗｲﾄｼｱﾝ B6Y04A | M26: 純正 | N26: 41900
B27: RICOH SP ﾄﾅ-ｶ-ﾄﾘﾂｼﾞ3700 | C27: RICOH | E27: 自動 | G27: 11641 | H27: 11641 | K27: B822dn | L27: OKI ﾚｰｻﾞｰﾌﾟﾘﾝﾀｰ B822dn | N27: 128000
B28: RICOH SP ﾄﾅ-ｶ-ﾄﾘﾂｼﾞ3700H | C28: RICOH | E28: 自動 | G28: 19162 | H28: 19162 | K28: B842dn | L28: OKI ﾚｰｻﾞｰﾌﾟﾘﾝﾀｰ B842dn | N28: 168000
B29: IPSIO SP ﾄﾅ-ｶ-ﾄﾘﾂｼﾞ 3400 | C29: RICOH | E29: 自動 | G29: 7426 | H29: 7426 | K29: B842dnt | L29: OKI ﾚｰｻﾞｰﾌﾟﾘﾝﾀｰ B842dnt | N29: 198000
B30: IPSIO SP ﾄﾅ-ｶ-ﾄﾘﾂｼﾞ 3400H | C30: RICOH | E30: 自動 | G30: 13240 | H30: 13240 | K30: BPTL700 | L30: SHARP BPTL700 一次転写ｸﾘｰﾅｰﾌﾞﾚｰﾄﾞ | M30: 純正
B31: IPSIO SP ECﾄﾅ-ｶ-ﾄﾘﾂｼﾞ 3400H | C31: RICOH | E31: 自動 | G31: 11812 | H31: 11812 | K31: C1P70A | L31: ADF ﾛｰﾗｰｷｯﾄ C1P70A | M31: 純正 | N31: 14882
B32: RICOH SP ﾄﾅ-ｶ-ﾄﾘﾂｼﾞ2300 | C32: RICOH | E32: 自動 | G32: 6690 | H32: 6690 | K32: C2410SD | L32: 富士ﾌｲﾙﾑ ﾚｰｻﾞｰﾌﾟﾘﾝﾀｰ ApeosPort Print C2410SD (NC100608) | M32: 純正
B33: RICOH SP ﾄﾅ-ｶ-ﾄﾘﾂｼﾞ2300H | C33: RICOH | E33: 自動 | G33: 13734 | H33: 13734 | K33: C4570 | L33: 富士ﾌｲﾙﾑ ﾚｰｻﾞｰﾌﾟﾘﾝﾀｰ ApeosPrint C4570 (NC100646) | M33: 純正 | N33: 442000
B34: RICOH SP ﾄﾅ-ｶ-ﾄﾘﾂｼﾞ2100 | C34: RICOH | E34: 自動 | G34: 6690 | H34: 6690 | K34: C650dnw | L34: OKI ﾚｰｻﾞｰﾌﾟﾘﾝﾀｰ C650dnw | N34: 178000
B35: RICOH SP ﾄﾅ-ｶ-ﾄﾘﾂｼﾞ2100H | C35: RICOH | E35: 自動 | G35: 13839 | H35: 13839 | K35: C6656AA | L35: -終息- HP56ﾌﾟﾘﾝﾄｶｰﾄﾘｯｼﾞ 黒 C6656AA#003 | M35: 純正
B36: RICOH SP ﾄﾅ- ｼｱﾝ C840 | C36: RICOH | E36: 自動 | G36: 17394 | H36: 17394 | K36: C7977A | L36: HP LTO7 Ultrium 15TB RW ﾃﾞｰﾀｶｰﾄﾘｯｼﾞ C7977A | M36: 純正 | N36: 32000
B37: RICOH SP ﾄﾅ- ﾏｾﾞﾝﾀ C840 | C37: RICOH | E37: 自動 | G37: 17394 | H37: 17394 | K37: C811dn | L37: OKI COREFIDO C811dn | M37: 純正
B38: RICOH SP ﾄﾅ- ｲｴﾛ- C840 | C38: RICOH | E38: 自動 | G38: 17394 | H38: 17394 | K38: C824dn | L38: OKI ﾚｰｻﾞｰﾌﾟﾘﾝﾀｰ C824dn
B39: RICOH SP ﾄﾅ- ﾌﾞﾗﾂｸ C840 | C39: RICOH | E39: 自動 | G39: 17729 | H39: 17729 | K39: C835dnw | L39: OKI ﾚｰｻﾞｰｶﾗｰﾌﾟﾘﾝﾀｰ C835dnw | N39: 178000
B40: RICOH SP ﾄﾅ- ｼｱﾝ C840H | C40: RICOH | E40: 自動 | G40: 26749 | H40: 26749 | K40: C844dnw | L40: OKI ﾚｰｻﾞｰｶﾗｰﾌﾟﾘﾝﾀｰ C844dnw | N40: 248000
...
